<?xml version="1.0"?>

<robot name="robobot">
    

    <material name="blue">
        <color rgba="0 0 0.8 1"/>
    </material>
     <material name="green">
        <color rgba="0 0.8 0 1"/>
    </material>


    <link name="base_link">
        <visual>
            <origin xyz="0.0 0.0 0" rpy="0.0 0.0 0.0"/>
            <geometry>
                <mesh filename="package://robobot/urdf/board.stl"  scale="0.1 0.1 0.1"/>
            </geometry>
            <material name="blue"/>   
        </visual>
        
    </link>









<joint name="left_wheel_joint" type="continuous">
    <parent link="base_link"/>
    <child link="left_wheel"/>
    <origin xyz="-0.35 0 0.075" rpy="0 0 0"/>
    <axis xyz="1 0 0"/>
</joint>

    <link name="left_wheel">
        <visual>
           <origin xyz="0 0 -0.075" rpy="0 0 1.57"/>
           <geometry>
               <mesh filename="package://robobot/urdf/wheel1.stl" scale="0.1 0.1 0.1"/>
           </geometry> 
           
        </visual>
    </link>




<joint name="right_wheel_joint" type="continuous">
    <parent link="base_link"/>
    <child link="right_wheel"/>
    <origin xyz="0.35 0 0.075" rpy="0 0 0"/>
    <axis xyz="1 0 0"/>
</joint>

    <link name="right_wheel">
        <visual>
           <origin xyz="0 0 -0.075" rpy="0 0 -1.57"/>
           <geometry>
               <mesh filename="package://robobot/urdf/wheel1.stl" scale="0.1 0.1 0.1"/>
           </geometry> 
           
        </visual>
    </link>



<link name="base_footprint">
	<visual>
		<origin xyz="0 0 0" rpy="0 0 0" />
		<geometry>
			<cylinder length="0.001" radius="0.010" />
		</geometry>
		<material name="green" />
	</visual>
</link>
<joint name="base_footprint_to_base_link" type="fixed">
	<origin xyz="0 0 0.15" rpy="0 0 0" />
	<parent link="base_footprint" />
	<child link="base_link" />
</joint>

    

</robot>     
